Traceback (most recent call last):
  File "/opt/hostedtoolcache/Python/3.8.12/x64/lib/python3.8/site-packages/jupyter_cache/executors/utils.py", line 51, in single_nb_execution
    executenb(
  File "/opt/hostedtoolcache/Python/3.8.12/x64/lib/python3.8/site-packages/nbclient/client.py", line 1204, in execute
    return NotebookClient(nb=nb, resources=resources, km=km, **kwargs).execute()
  File "/opt/hostedtoolcache/Python/3.8.12/x64/lib/python3.8/site-packages/nbclient/util.py", line 84, in wrapped
    return just_run(coro(*args, **kwargs))
  File "/opt/hostedtoolcache/Python/3.8.12/x64/lib/python3.8/site-packages/nbclient/util.py", line 62, in just_run
    return loop.run_until_complete(coro)
  File "/opt/hostedtoolcache/Python/3.8.12/x64/lib/python3.8/asyncio/base_events.py", line 616, in run_until_complete
    return future.result()
  File "/opt/hostedtoolcache/Python/3.8.12/x64/lib/python3.8/site-packages/nbclient/client.py", line 663, in async_execute
    await self.async_execute_cell(
  File "/opt/hostedtoolcache/Python/3.8.12/x64/lib/python3.8/site-packages/nbclient/client.py", line 965, in async_execute_cell
    await self._check_raise_for_error(cell, cell_index, exec_reply)
  File "/opt/hostedtoolcache/Python/3.8.12/x64/lib/python3.8/site-packages/nbclient/client.py", line 862, in _check_raise_for_error
    raise CellExecutionError.from_cell_and_msg(cell, exec_reply_content)
nbclient.exceptions.CellExecutionError: An error occurred while executing the following cell:
------------------
# This extracts the documents in the document root
with zipfile.ZipFile(data_path) as zf:
    zf.extractall(data_root)
------------------

[0;31m---------------------------------------------------------------------------[0m
[0;31mFileNotFoundError[0m                         Traceback (most recent call last)
Input [0;32mIn [5][0m, in [0;36m<cell line: 2>[0;34m()[0m
[1;32m      1[0m [38;5;66;03m# This extracts the documents in the document root[39;00m
[0;32m----> 2[0m [38;5;28;01mwith[39;00m [43mzipfile[49m[38;5;241;43m.[39;49m[43mZipFile[49m[43m([49m[43mdata_path[49m[43m)[49m [38;5;28;01mas[39;00m zf:
[1;32m      3[0m     zf[38;5;241m.[39mextractall(data_root)

File [0;32m/opt/hostedtoolcache/Python/3.8.12/x64/lib/python3.8/zipfile.py:1251[0m, in [0;36mZipFile.__init__[0;34m(self, file, mode, compression, allowZip64, compresslevel, strict_timestamps)[0m
[1;32m   1249[0m [38;5;28;01mwhile[39;00m [38;5;28;01mTrue[39;00m:
[1;32m   1250[0m     [38;5;28;01mtry[39;00m:
[0;32m-> 1251[0m         [38;5;28mself[39m[38;5;241m.[39mfp [38;5;241m=[39m [43mio[49m[38;5;241;43m.[39;49m[43mopen[49m[43m([49m[43mfile[49m[43m,[49m[43m [49m[43mfilemode[49m[43m)[49m
[1;32m   1252[0m     [38;5;28;01mexcept[39;00m [38;5;167;01mOSError[39;00m:
[1;32m   1253[0m         [38;5;28;01mif[39;00m filemode [38;5;129;01min[39;00m modeDict:

[0;31mFileNotFoundError[0m: [Errno 2] No such file or directory: 'data/sampled_archive.zip'
FileNotFoundError: [Errno 2] No such file or directory: 'data/sampled_archive.zip'

